Workbook

Sheet Resumen
A1: Green Alliance — tablero de avances
A2: Actualizado: 2026-10-23. Lo mantiene el agente ga-supervisor-avances a partir de docs/avances/plan.json.
B4: Parámetros
B5: Bloques por semana | C5: 10 | D5: 1 bloque = 1 punto de peso ≈ media jornada de trabajo. Se puede cambiar en la hoja Resumen.
B6: HOY (bloque donde termina lo hecho) | C6: 134 | D6: Calculado por el optimizador.
B8: Indicadores
B9: Actividades en el plan | C9: =COUNTA(Plan!$A$5:$A$129)
B10: Hechas | C10: =COUNTIF(Plan!$O$5:$O$129,"Hecho")
B11: En curso | C11: =COUNTIF(Plan!$O$5:$O$129,"En curso")
B12: Pendientes | C12: =COUNTIF(Plan!$O$5:$O$129,"Pendiente")
B13: Bloqueadas (esperan a la cooperativa) | C13: =COUNTIF(Plan!$O$5:$O$129,"Bloqueado")
B14: Peso total (puntos) | C14: =SUM(Plan!$D$5:$D$129)
B15: Peso hecho (puntos) | C15: =SUMIF(Plan!$O$5:$O$129,"Hecho",Plan!$D$5:$D$129)
B16: Avance ponderado por peso | C16: =IF(C14=0,0,C15/C14)
B17: Duración total optimizada (bloques) | C17: =MAX(Plan!$L$5:$L$129)
B18: Duración total optimizada (semanas) | C18: =C17/C5
B19: Si se hiciera en una sola fila (bloques) | C19: =C14
B20: Si se hiciera en una sola fila (semanas) | C20: =C19/C5
B21: Tiempo ahorrado con 2 filas | C21: =IF(C19=0,0,1-C17/C19)
B22: Falta desde HOY (semanas) | C22: =(C17-C6)/C5
B23: Uso de la Fila A | C23: =IF(C17=0,0,(SUMIF(Plan!$I$5:$I$129,"A",Plan!$E$5:$E$129)+SUMIF(Plan!$I$5:$I$129,"A+B",Plan!$E$5:$E$129))/C17)
B24: Uso de la Fila B | C24: =IF(C17=0,0,(SUMIF(Plan!$I$5:$I$129,"B",Plan!$E$5:$E$129)+SUMIF(Plan!$I$5:$I$129,"A+B",Plan!$E$5:$E$129))/C17)
B25: Plazo de la propuesta (semanas) | C25: =MAX('Propuesta original'!E5:E10)
B27: Avance por fase
B28: Fase | C28: Peso total | D28: Peso hecho | E28: Avance | F28: Termina (bloque) | G28: Termina (semana) | H28: Propuesta (semanas)
B29: 1. Diseño y arquitectura | C29: =SUMIF(Plan!$B$5:$B$129,"1. Diseño y arquitectura",Plan!$D$5:$D$129) | D29: =SUMIFS(Plan!$D$5:$D$129,Plan!$B$5:$B$129,"1. Diseño y arquitectura",Plan!$O$5:$O$129,"Hecho") | E29: =IF(C29=0,0,D29/C29) | F29: =SUMPRODUCT(MAX((Plan!$B$5:$B$129="1. Diseño y arquitectura")*Plan!$L$5:$L$129)) | G29: ="S"&ROUNDUP(F29/$C$5,0) | H29: ='Propuesta original'!E5
B30: 2. Landing y autenticación | C30: =SUMIF(Plan!$B$5:$B$129,"2. Landing y autenticación",Plan!$D$5:$D$129) | D30: =SUMIFS(Plan!$D$5:$D$129,Plan!$B$5:$B$129,"2. Landing y autenticación",Plan!$O$5:$O$129,"Hecho") | E30: =IF(C30=0,0,D30/C30) | F30: =SUMPRODUCT(MAX((Plan!$B$5:$B$129="2. Landing y autenticación")*Plan!$L$5:$L$129)) | G30: ="S"&ROUNDUP(F30/$C$5,0) | H30: ='Propuesta original'!E6
B31: 3. Flujo de solicitud de crédito | C31: =SUMIF(Plan!$B$5:$B$129,"3. Flujo de solicitud de crédito",Plan!$D$5:$D$129) | D31: =SUMIFS(Plan!$D$5:$D$129,Plan!$B$5:$B$129,"3. Flujo de solicitud de crédito",Plan!$O$5:$O$129,"Hecho") | E31: =IF(C31=0,0,D31/C31) | F31: =SUMPRODUCT(MAX((Plan!$B$5:$B$129="3. Flujo de solicitud de crédito")*Plan!$L$5:$L$129)) | G31: ="S"&ROUNDUP(F31/$C$5,0) | H31: ='Propuesta original'!E7
B32: 4. Panel de administración | C32: =SUMIF(Plan!$B$5:$B$129,"4. Panel de administración",Plan!$D$5:$D$129) | D32: =SUMIFS(Plan!$D$5:$D$129,Plan!$B$5:$B$129,"4. Panel de administración",Plan!$O$5:$O$129,"Hecho") | E32: =IF(C32=0,0,D32/C32) | F32: =SUMPRODUCT(MAX((Plan!$B$5:$B$129="4. Panel de administración")*Plan!$L$5:$L$129)) | G32: ="S"&ROUNDUP(F32/$C$5,0) | H32: ='Propuesta original'!E8
B33: 5. Convenios y pulido | C33: =SUMIF(Plan!$B$5:$B$129,"5. Convenios y pulido",Plan!$D$5:$D$129) | D33: =SUMIFS(Plan!$D$5:$D$129,Plan!$B$5:$B$129,"5. Convenios y pulido",Plan!$O$5:$O$129,"Hecho") | E33: =IF(C33=0,0,D33/C33) | F33: =SUMPRODUCT(MAX((Plan!$B$5:$B$129="5. Convenios y pulido")*Plan!$L$5:$L$129)) | G33: ="S"&ROUNDUP(F33/$C$5,0) | H33: ='Propuesta original'!E9
B34: 6. Pruebas y lanzamiento | C34: =SUMIF(Plan!$B$5:$B$129,"6. Pruebas y lanzamiento",Plan!$D$5:$D$129) | D34: =SUMIFS(Plan!$D$5:$D$129,Plan!$B$5:$B$129,"6. Pruebas y lanzamiento",Plan!$O$5:$O$129,"Hecho") | E34: =IF(C34=0,0,D34/C34) | F34: =SUMPRODUCT(MAX((Plan!$B$5:$B$129="6. Pruebas y lanzamiento")*Plan!$L$5:$L$129)) | G34: ="S"&ROUNDUP(F34/$C$5,0) | H34: ='Propuesta original'!E10
B36: Hitos de pago (propuesta)
B37: Pago | C37: Valor (COP) | D37: Fase | E37: Se libera en | F37: Bloque | G37: Semana | H37: Estado del hito
B38: Adelanto | C38: 500000 | D38: 1 | E38: Al iniciar el proyecto (Fase 1) | F38: 0 | G38: S1 | H38: ="Cumplido (inicio)"
B39: Pago 2 | C39: 800000 | D39: 3 | E39: Login y flujo de solicitud de crédito funcionando (fin Fase 3) | F39: =F31 | G39: =G31 | H39: =IF(E31=1,"Cumplido","Falta "&TEXT(1-E31,"0%"))
B40: Pago 3 | C40: 800000 | D40: 4 | E40: Panel de administración funcionando (fin Fase 4) | F40: =F32 | G40: =G32 | H40: =IF(E32=1,"Cumplido","Falta "&TEXT(1-E32,"0%"))
B41: Pago final | C41: 900000 | D41: 6 | E41: Entrega en producción (fin Fase 6) | F41: =F34 | G41: =G34 | H41: =IF(E34=1,"Cumplido","Falta "&TEXT(1-E34,"0%"))
B42: Total | C42: =SUM(C38:C41)
B44: Pendientes por categoría (hoja Pendientes)
B45: Categoría | C45: Hecho | D45: En curso | E45: Pendiente | F45: Bloqueado | G45: Total
...

Sheet Pendientes
A1: Pendientes organizados
A2: Ordenados por categoría, estado y prioridad. «Actividad del plan» enlaza con la hoja Plan / Gantt.
A4: ID | B4: Categoría | C4: Área / pantalla | D4: Tarea | E4: Responsable | F4: Prioridad | G4: Estado | H4: Actividad del plan | I4: Fase de la actividad | J4: Nota
A5: P-145 | B5: Configuración | C5: Base de datos | D5: Correr pgTAP 35 y 36 cuando tenga Docker (las migraciones 20261022000000 y 20261023000000 ya están aplicadas; hoy el PC no tiene la virtualización activa) | E5: Sebas | F5: Alta | G5: Pendiente | H5: 6.44 | I5: =IFERROR(INDEX(Plan!$B$5:$B$129,MATCH(H5,Plan!$A$5:$A$129,0)),"—") | J5: 23-oct: migraciones aplicadas y verificadas con migration list --linked; queda solo pgTAP.
A6: P-105 | B6: Configuración | C6: Vercel/Resend | D6: CRON_SECRET de 32+ caracteres, publicar plantilla ga-aviso-institucional y crear RESEND_TEMPLATE_AVISO_INSTITUCIONAL | E6: Sebas | F6: Alta | G6: Hecho | H6: 6.22 | I6: =IFERROR(INDEX(Plan!$B$5:$B$129,MATCH(H6,Plan!$A$5:$A$129,0)),"—") | J6: 30-sep: Sebas lo hizo en producción.
A7: P-110 | B7: Configuración | C7: Base de datos | D7: Aplicar la migración 20261001000000 antes de desplegar (sin ella falla el insert de afiliación por la columna version_politica_datos) | E7: Sebas | F7: Alta | G7: Hecho | H7: 6.23 | I7: =IFERROR(INDEX(Plan!$B$5:$B$129,MATCH(H7,Plan!$A$5:$A$129,0)),"—") | J7: 30-sep: reportado por ga-auditor-supabase y ga-funcionalidad-botones. 01-oct: aplicada en producción.
A8: P-113 | B8: Configuración | C8: Base de datos | D8: Docker: db reset + test db local y aplicar la migración 20261001100000 en producción | E8: Sebas | F8: Alta | G8: Hecho | H8: 6.24 | I8: =IFERROR(INDEX(Plan!$B$5:$B$129,MATCH(H8,Plan!$A$5:$A$129,0)),"—") | J8: 01-oct: Docker Desktop no arranca («unable to start»). 01-oct: Docker de vuelta; db test local en verde (22 archivos, 497 pruebas). Falta solo db push --linked de 20261001000000 y 20261001100000 y fusionar develop→main. 01-oct: 20261001000000 y 20261001100000 aplicadas en producción.
A9: P-114 | B9: Configuración | C9: Base de datos | D9: Aplicar la migración 20261002000000 en producción y fusionar develop→main (commit e2523de) | E9: Sebas | F9: Alta | G9: Hecho | H9: 6.25 | I9: =IFERROR(INDEX(Plan!$B$5:$B$129,MATCH(H9,Plan!$A$5:$A$129,0)),"—") | J9: 01-oct: sin ella /admin/convenios y la lectura de convenios por visible/orden fallan en producción (el loader tiene respaldo en CONVENIOS). Probar subida de logo con un admin real. 02-oct: cerrada; la fusión develop→main sigue en P-116 (6.27).
A10: P-116 | B10: Configuración | C10: Base de datos | D10: Aplicar con respaldo previo 20261002500000, 20261002600000, 20261003000000, 20261003100000 y 20261003200000 y 20261003300000 y fusionar develop→main | E10: Sebas | F10: Alta | G10: Hecho | H10: 6.27 | I10: =IFERROR(INDEX(Plan!$B$5:$B$129,MATCH(H10,Plan!$A$5:$A$129,0)),"—") | J10: 02-oct: 20261003000000 quita la FK perfiles.id → auth.users (cascada por trigger). 09-oct: Hecho por Sebas.
A11: P-117 | B11: Configuración | C11: Correos | D11: Plantilla del sorteo en Vercel/Resend (variables NOMBRE, NUMERO_BOLETA, MES) y {{{COMPROBANTE}}} en la plantilla de desembolso | E11: Sebas | F11: Alta | G11: Hecho | H11: 6.28 | I11: =IFERROR(INDEX(Plan!$B$5:$B$129,MATCH(H11,Plan!$A$5:$A$129,0)),"—") | J11: 02-oct: sin la plantilla, el correo del sorteo cae a texto plano (docs/resend-plantillas.md). 09-oct: Hecho por Sebas.
A12: P-135 | B12: Configuración | C12: Base de datos | D12: Aplicar la migración 20261008000000 (Patrullero de Policía) con respaldo previo | E12: Sebas | F12: Alta | G12: Hecho | H12: 6.36 | I12: =IFERROR(INDEX(Plan!$B$5:$B$129,MATCH(H12,Plan!$A$5:$A$129,0)),"—") | J12: 08-oct: db push, verificando antes migration list --linked. 09-oct: Hecho por Sebas.
A13: P-138 | B13: Configuración | C13: Base de datos | D13: Aplicar con respaldo previo la migración 20261009000000 (hallazgos de seguridad del 8-oct), verificando antes migration list --linked | E13: Sebas | F13: Alta | G13: Hecho | H13: 6.39 | I13: =IFERROR(INDEX(Plan!$B$5:$B$129,MATCH(H13,Plan!$A$5:$A$129,0)),"—") | J13: 09-oct: incluye la RPC fotos_carne_huerfanas. Sin ella el código nuevo no funciona. 09-oct: Hecho por Sebas.
A14: P-139 | B14: Configuración | C14: Despliegue | D14: Desplegar el código nuevo de inmediato junto con la migración 20261009000000 | E14: Sebas | F14: Alta | G14: Hecho | H14: 6.40 | I14: =IFERROR(INDEX(Plan!$B$5:$B$129,MATCH(H14,Plan!$A$5:$A$129,0)),"—") | J14: 09-oct: código y migración van juntos. Desactivar a un admin ya no se puede desde la app; si la cooperativa lo necesita, hace falta otra migración. 09-oct: Hecho por Sebas.
A15: P-141 | B15: Configuración | C15: Base de datos | D15: Aplicar la migración 20261014000000 (afiliación sin repetidos) con db push y correr pgTAP con Docker | E15: Sebas | F15: Alta | G15: Hecho | H15: 6.41 | I15: =IFERROR(INDEX(Plan!$B$5:$B$129,MATCH(H15,Plan!$A$5:$A$129,0)),"—") | J15: 18-oct: aplicada por Sebas; pgTAP en verde.
A16: P-142 | B16: Configuración | C16: Base de datos | D16: Aplicar la migración 20261018000000 (pausa de cuenta y avisos) con db push y correr pgTAP 33 con Docker | E16: Sebas | F16: Alta | G16: Hecho | H16: 6.41 | I16: =IFERROR(INDEX(Plan!$B$5:$B$129,MATCH(H16,Plan!$A$5:$A$129,0)),"—") | J16: 18-oct: aplicada por Sebas; pgTAP 33 en verde. La prueba de selfie en celular real pasó a P-143.
... A35: P-56 | B35: Funcionalidad | C35: /cuenta/solicitar | D35: Revisar el diseño de /cuenta/solicitar (sin maqueta; selector 50/100 como radios) | E35: ga-diseno-a-codigo | F35: Media | G35: Pendiente | H35: 5.6 | I35: =IFERROR(INDEX(Plan!$B$5:$B$129,MATCH(H35,Plan!$A$5:$A$129,0)),"—") | J35: Pedido por ga-funcionalidad-botones el 23-sep.
A36: P-22 | B36: Funcionalidad | C36: /ingresar | D36: Server Action: correo_por_cedula(), signInWithOtp, cookie firmada, ir a /ingresar/codigo | E36: ga-funcionalidad-botones | F36: Alta | G36: Hecho | H36: 2.5 | I36: =IFERROR(INDEX(Plan!$B$5:$B$129,MATCH(H36,Plan!$A$5:$A$129,0)),"—")
A37: P-24 | B37: Funcionalidad | C37: /ingresar/codigo | D37: Leer la cookie del paso 1; sin cookie, volver a /ingresar | E37: ga-funcionalidad-botones | F37: Alta | G37: Hecho | H37: 2.6 | I37: =IFERROR(INDEX(Plan!$B$5:$B$129,MATCH(H37,Plan!$A$5:$A$129,0)),"—")
A38: P-25 | B38: Funcionalidad | C38: /ingresar/codigo | D38: verifyOtp y entrar a /cuenta | E38: ga-funcionalidad-botones | F38: Alta | G38: Hecho | H38: 2.6 | I38: =IFERROR(INDEX(Plan!$B$5:$B$129,MATCH(H38,Plan!$A$5:$A$129,0)),"—")
A39: P-28 | B39: Funcionalidad | C39: /afiliacion | D39: Server Action: zod, límites por IP y cédula, guardar | E39: ga-funcionalidad-botones | F39: Alta | G39: Hecho | H39: 2.9 | I39: =IFERROR(INDEX(Plan!$B$5:$B$129,MATCH(H39,Plan!$A$5:$A$129,0)),"—") | J39: 23-sep: se quitaron los correos al equipo y al solicitante (decisión de Sebas). El equipo revisa las afiliaciones en Supabase hasta que exista el panel /admin; el correo «Ingreso aceptado» sale al aprobar (P-51).
A40: P-31 | B40: Funcionalidad | C40: /cuenta | D40: Proteger con proxy.ts y «Salir» con signOut | E40: ga-funcionalidad-botones | F40: Alta | G40: Hecho | H40: 2.7 | I40: =IFERROR(INDEX(Plan!$B$5:$B$129,MATCH(H40,Plan!$A$5:$A$129,0)),"—")
A41: P-32 | B41: Funcionalidad | C41: /cuenta | D41: Cargar perfil, última solicitud (con tasa), tope y convenios | E41: ga-funcionalidad-botones | F41: Alta | G41: Hecho | H41: 3.5 | I41: =IFERROR(INDEX(Plan!$B$5:$B$129,MATCH(H41,Plan!$A$5:$A$129,0)),"—")
A42: P-35 | B42: Funcionalidad | C42: Crédito | D42: Conectar el formulario de crédito a /cuenta | E42: ga-funcionalidad-botones | F42: Alta | G42: Hecho | H42: 3.7 | I42: =IFERROR(INDEX(Plan!$B$5:$B$129,MATCH(H42,Plan!$A$5:$A$129,0)),"—") | J42: 23-sep: el formulario vive en /cuenta/solicitar (protegida por proxy.ts, encabezado compartido EncabezadoCuenta); «Nueva solicitud» lleva ahí.
A43: P-36 | B43: Funcionalidad | C43: Admin | D43: Panel /admin: listado, aprobar y rechazar con motivo | E43: ga-funcionalidad-botones | F43: Alta | G43: Hecho | H43: 4.1 | I43: =IFERROR(INDEX(Plan!$B$5:$B$129,MATCH(H43,Plan!$A$5:$A$129,0)),"—") | J43: 24-sep: implementado y probado en local (commits 235ffbe, a13c2de). Un admin no puede resolver su propia solicitud.
A44: P-37 | B44: Funcionalidad | C44: Correos | D44: Correo «Resultado del crédito» (aprobado / no aprobado) al asociado al resolver una solicitud | E44: ga-funcionalidad-botones | F44: Alta | G44: Hecho | H44: 4.3 | I44: =IFERROR(INDEX(Plan!$B$5:$B$129,MATCH(H44,Plan!$A$5:$A$129,0)),"—") | J44: 24-sep: enviarResultadoCredito ya está conectado al aprobar/rechazar en /admin (probado en local); falta que Sebas configure el SMTP/Resend de producción (2.4) para que salga de verdad.
A45: P-38 | B45: Funcionalidad | C45: Asociados | D45: Importación de asociados desde Excel | E45: ga-funcionalidad-botones | F45: Alta | G45: Hecho | H45: 4.4 | I45: =IFERROR(INDEX(Plan!$B$5:$B$129,MATCH(H45,Plan!$A$5:$A$129,0)),"—") | J45: Ya no aplica: decisión de la cooperativa 2026-09-24, no habrá importación de Excel.
A46: P-51 | B46: Funcionalidad | C46: Correos | D46: Correo «Ingreso aceptado» (plantilla ga-ingreso-aceptado): acción del admin que aprueba la afiliación, crea el usuario y envía el correo | E46: ga-funcionalidad-botones | F46: Alta | G46: Hecho | H46: 4.5 | I46: =IFERROR(INDEX(Plan!$B$5:$B$129,MATCH(H46,Plan!$A$5:$A$129,0)),"—") | J46: 01-oct: verificado en el código: aprobarAfiliacion (app/admin/afiliaciones/actions.ts) crea el usuario y envía enviarIngresoAceptado (lib/correo/ingreso.ts).
A47: P-66 | B47: Funcionalidad | C47: Admin | D47: Dashboard de clientes en /admin: métricas (asociados por grado/institución, afiliaciones y créditos pendientes, montos del mes, inscritos al sorteo), lista con buscador/filtros, detalle de cliente y reasignar asesor | E47: Carlos Pardo | F47: Alta | G47: Hecho | H47: 4.7 | I47: =IFERROR(INDEX(Plan!$B$5:$B$129,MATCH(H47,Plan!$A$5:$A$129,0)),"—") | J47: Encargo externo (500.000 COP) por PR a develop. Ver P-73. 30-sep: Carlos salió; pasa a ga-funcionalidad-botones. 01-oct: verificado en el código y cerrado con 4.7 (ResumenAdmin, /admin/asociados con buscador y detalle, asignarAsesor). «Inscritos al sorteo» sigue en P-111.
A48: P-67 | B48: Funcionalidad | C48: Asesor | D48: Dashboard del asesor en /asesor: métricas de sus clientes y detalle de cliente sin celular, correo, Nequi ni fotos | E48: Carlos Pardo | F48: Alta | G48: Hecho | H48: 4.8 | I48: =IFERROR(INDEX(Plan!$B$5:$B$129,MATCH(H48,Plan!$A$5:$A$129,0)),"—") | J48: Encargo externo (500.000 COP) por PR a develop. Ver P-73. 30-sep: Carlos salió; pasa a ga-funcionalidad-botones. 01-oct: verificado en el código y cerrado con 4.8 (/asesor con métricas; el loader no selecciona celular, correo, Nequi ni fotos).
A49: P-69 | B49: Funcionalidad | C49: Legal | D49: Ley 1581: borrado automático de fotos de afiliaciones rechazadas tras X días y motivo de rechazo en /admin | E49: Carlos Pardo | F49: Alta | G49: Hecho | H49: 5.10 | I49: =IFERROR(INDEX(Plan!$B$5:$B$129,MATCH(H49,Plan!$A$5:$A$129,0)),"—") | J49: Encargo externo (500.000 COP) por PR a develop. Falta que la cooperativa dé el X de días (ver P-63). Ver P-73. 29-sep: primera entrega (ZIP, base main anterior al rediseño C+) NO fusionable — reintroduce F2-03, pierde el revoke en resumen_clientes_asesor, columna de motivo de rechazo inexistente sin migración, purga con columnas/bucket equivocados y cron abierto sin CRON_SECRET, claves en .env.example, console.log, config de túnel, sin pruebas. Se le envió la lista de correcciones para rehacer sobre rediseno-c-plus, un PR por tarea. 30-sep: hecho por agentes (cron cada hora + RPC fotos_huerfanas_afiliacion).
A50: P-85 | B50: Funcionalidad | C50: /afiliacion | D50: Correo de afiliación acepta cualquier dominio (ya no exige @policia.gov.co / @ejercito.mil.co) | E50: sesión principal | F50: Alta | G50: Hecho | H50: 2.12 | I50: =IFERROR(INDEX(Plan!$B$5:$B$129,MATCH(H50,Plan!$A$5:$A$129,0)),"—") | J50: 25-sep: esquema zod, campo del formulario y pruebas (unitarias, e2e, pgTAP) actualizados; migración 20260925194922_correo_afiliacion_cualquier_dominio aplicada en producción (base de datos) y el archivo local renombrado a esa versión para que el historial coincida. F-01 revisado: la máscara del correo ahora oculta también el dominio («ju•••@•••»). 25-sep: desplegado con el PR #2 (merge 2c19d02); confirmado en vivo que /afiliacion ya no exige correo institucional.
A51: P-112 | B51: Funcionalidad | C51: Pruebas | D51: Agregar admin_metricas_dashboard y asesor_metricas_dashboard a las listas blancas de security definer (pgTAP 00 #14 y 15 #24) | E51: ga-escritor-tests | F51: Media | G51: Hecho | H51: 6.21 | I51: =IFERROR(INDEX(Plan!$B$5:$B$129,MATCH(H51,Plan!$A$5:$A$129,0)),"—") | J51: 30-sep: reportado por ga-auditor-supabase. 01-oct: listas blancas de 00 y 15 actualizadas por ga-auditor-supabase (falta correrlas: Docker).
A52: P-23 | B52: Funcionalidad | C52: /ingresar | D52: Estado «Enviando…» (prop cargando) y errores (prop error) | E52: ga-funcionalidad-botones | F52: Media | G52: Hecho | H52: 2.5 | I52: =IFERROR(INDEX(Plan!$B$5:$B$129,MATCH(H52,Plan!$A$5:$A$129,0)),"—")
A53: P-26 | B53: Funcionalidad | C53: /ingresar/codigo | D53: Casillas OTP: avance automático, Backspace, pegar; «Entrar» con 6 dígitos | E53: ga-funcionalidad-botones | F53: Media | G53: Hecho | H53: 2.6 | I53: =IFERROR(INDEX(Plan!$B$5:$B$129,MATCH(H53,Plan!$A$5:$A$129,0)),"—")
A54: P-27 | B54: Funcionalidad | C54: /ingresar/codigo | D54: «Reenviar código» con contador de 45 s; «Cambiar cédula» limpia la cookie | E54: ga-funcionalidad-botones | F54: Media | G54: Hecho | H54: 2.6 | I54: =IFERROR(INDEX(Plan!$B$5:$B$129,MATCH(H54,Plan!$A$5:$A$129,0)),"—")
A55: P-29 | B55: Funcionalidad | C55: /afiliacion | D55: Grados desde grados_credito, honeypot, errores y estado de carga | E55: ga-funcionalidad-botones | F55: Media | G55: Hecho | H55: 2.9 | I55: =IFERROR(INDEX(Plan!$B$5:$B$129,MATCH(H55,Plan!$A$5:$A$129,0)),"—")
A56: P-33 | B56: Funcionalidad | C56: /cuenta | D56: «Mis datos»: actualizar solo perfiles.telefono | E56: ga-funcionalidad-botones | F56: Media | G56: Hecho | H56: 3.6 | I56: =IFERROR(INDEX(Plan!$B$5:$B$129,MATCH(H56,Plan!$A$5:$A$129,0)),"—") | J56: Con error, alinear «Guardar» con el campo desde 640 px.
A57: P-48 | B57: Funcionalidad | C57: /afiliacion | D57: F-01: el select «Grado» se vacía tras un error de validación | E57: ga-funcionalidad-botones | F57: Media | G57: Hecho | H57: 2.11 | I57: =IFERROR(INDEX(Plan!$B$5:$B$129,MATCH(H57,Plan!$A$5:$A$129,0)),"—") | J57: Falla media de la verificación QA 1 (docs/verificaciones/2026-09-23-verificacion-1.md). 01-oct: corregido (formulario se rehace con key; conserva Institución/Grado).
A58: P-57 | B58: Funcionalidad | C58: /asesor | D58: Agregar /asesor al matcher de proxy.ts y redirigir por rol tras el login | E58: ga-funcionalidad-botones | F58: Media | G58: Hecho | H58: 4.6 | I58: =IFERROR(INDEX(Plan!$B$5:$B$129,MATCH(H58,Plan!$A$5:$A$129,0)),"—") | J58: 01-oct: verificado en el código: /asesor en el matcher de proxy.ts y redirección por rol en app/ingresar/actions.ts.
A59: P-68 | B59: Funcionalidad | C59: Convenios | D59: Convenios administrables desde /admin (crear, editar, ocultar, ordenar, logo en Storage); landing y /cuenta leen de la tabla convenios | E59: Carlos Pardo | F59: Media | G59: Hecho | H59: 5.9 | I59: =IFERROR(INDEX(Plan!$B$5:$B$129,MATCH(H59,Plan!$A$5:$A$129,0)),"—") | J59: Encargo externo (500.000 COP) por PR a develop. Ver P-73. 30-sep: Carlos salió; pasa a ga-funcionalidad-botones. 01-oct: hecho por agentes (5.9); falta aplicar 20261002000000 (P-114).
...

Sheet Plan
A1: Plan optimizado — tabla de actividades
A2: Inicio, Listo y Fila los calcula el optimizador (2 filas, cola infinita). Si cambias pesos o dependencias, pide a ga-supervisor-avances que regenere el libro.
A4: ID | B4: Fase | C4: Actividad | D4: Peso (1–5) | E4: Duración (bloques) | F4: Depende de | G4: ¿Simultánea con otras? | H4: En paralelo con | I4: Fila | J4: Entra a la cola (bloque) | K4: Inicio (bloque) | L4: Fin (bloque) | M4: Espera en cola | N4: Semanas | O4: Estado | P4: Origen | Q4: Agente / responsable | R4: Bloqueo externo
A5: 1.1 | B5: 1. Diseño y arquitectura | C5: Diseño visual de las 6 pantallas (PC 1280 px y celular 390 px) | D5: 4 | E5: =D5 | F5: — | G5: Sí | H5: 1.3, 1.2 | I5: A | J5: 0 | K5: 0 | L5: =K5+E5 | M5: =K5-J5 | N5: ="S"&(INT(K5/Resumen!$C$5)+1)&"–S"&MAX(INT(K5/Resumen!$C$5)+1,ROUNDUP(L5/Resumen!$C$5,0)) | O5: Hecho | P5: Propuesta | Q5: —
A6: 1.2 | B6: 1. Diseño y arquitectura | C6: Modelo de datos en Supabase (perfiles, grados, solicitudes, convenios) | D6: 3 | E6: =D6 | F6: — | G6: Sí | H6: 1.1 | I6: B | J6: 0 | K6: 1 | L6: =K6+E6 | M6: =K6-J6 | N6: ="S"&(INT(K6/Resumen!$C$5)+1)&"–S"&MAX(INT(K6/Resumen!$C$5)+1,ROUNDUP(L6/Resumen!$C$5,0)) | O6: Hecho | P6: Propuesta | Q6: ga-auditor-supabase
A7: 1.3 | B7: 1. Diseño y arquitectura | C7: Stack y proyecto base (Next.js 16, Supabase, Resend) | D7: 1 | E7: =D7 | F7: — | G7: Sí | H7: 1.1 | I7: B | J7: 0 | K7: 0 | L7: =K7+E7 | M7: =K7-J7 | N7: ="S"&(INT(K7/Resumen!$C$5)+1)&"–S"&MAX(INT(K7/Resumen!$C$5)+1,ROUNDUP(L7/Resumen!$C$5,0)) | O7: Hecho | P7: Propuesta | Q7: —
A8: 1.4 | B8: 1. Diseño y arquitectura | C8: Tokens de diseño y componentes UI (Tailwind, globals.css) | D8: 2 | E8: =D8 | F8: 1.1, 1.3 | G8: Sí | H8: 2.4 | I8: A | J8: 4 | K8: 4 | L8: =K8+E8 | M8: =K8-J8 | N8: ="S"&(INT(K8/Resumen!$C$5)+1)&"–S"&MAX(INT(K8/Resumen!$C$5)+1,ROUNDUP(L8/Resumen!$C$5,0)) | O8: Hecho | P8: Propuesta | Q8: ga-diseno-a-codigo
A9: 1.5 | B9: 1. Diseño y arquitectura | C9: Modelo de datos fase 2: rol asesor, afiliación v2 (fotos), bucket privado de documentos y sorteo mensual (6 migraciones + seed) | D9: 5 | E9: =D9 | F9: 1.2 | G9: Sí | H9: 2.6, 1.7, 2.14 | I9: B | J9: 4 | K9: 13 | L9: =K9+E9 | M9: =K9-J9 | N9: ="S"&(INT(K9/Resumen!$C$5)+1)&"–S"&MAX(INT(K9/Resumen!$C$5)+1,ROUNDUP(L9/Resumen!$C$5,0)) | O9: Hecho | P9: Agregado | Q9: ga-auditor-supabase
A10: 1.6 | B10: 1. Diseño y arquitectura | C10: Auditoría de las migraciones de fase 2 y 3 migraciones correctivas de seguridad (boleta del sorteo oculta, asesor degradado, trigger de sincronía app_metadata) | D10: 3 | E10: =D10 | F10: 1.5 | G10: Sí | H10: 4.10, 2.17 | I10: B | J10: 18 | K10: 33 | L10: =K10+E10 | M10: =K10-J10 | N10: ="S"&(INT(K10/Resumen!$C$5)+1)&"–S"&MAX(INT(K10/Resumen!$C$5)+1,ROUNDUP(L10/Resumen!$C$5,0)) | O10: Hecho | P10: Agregado | Q10: ga-auditor-supabase
A11: 1.7 | B11: 1. Diseño y arquitectura | C11: Rediseño C+: design system y tokens (colores claro/oscuro, tipografía, radios, sombras, movimiento) en el lienzo y en globals.css/tailwind.config.ts | D11: 2 | E11: =D11 | F11: 1.4 | G11: Sí | H11: 1.5 | I11: A | J11: 6 | K11: 14 | L11: =K11+E11 | M11: =K11-J11 | N11: ="S"&(INT(K11/Resumen!$C$5)+1)&"–S"&MAX(INT(K11/Resumen!$C$5)+1,ROUNDUP(L11/Resumen!$C$5,0)) | O11: Hecho | P11: Agregado | Q11: ga-disenador-lienzo + ga-diseno-a-codigo
A12: 1.8 | B12: 1. Diseño y arquitectura | C12: Backend del rediseño C+: revisar y aplicar 5 migraciones propuestas (aviso del sorteo, institución/activo en perfiles, historial + nota interna del admin, Realtime de solicitudes, índices de búsqueda) | D12: 2 | E12: =D12 | F12: 1.6 | G12: Sí | H12: 6.17 | I12: A | J12: 36 | K12: 36 | L12: =K12+E12 | M12: =K12-J12 | N12: ="S"&(INT(K12/Resumen!$C$5)+1)&"–S"&MAX(INT(K12/Resumen!$C$5)+1,ROUNDUP(L12/Resumen!$C$5,0)) | O12: Hecho | P12: Agregado | Q12: Sebas (ga-auditor-supabase revisa antes)
A13: 2.1 | B13: 2. Landing y autenticación | C13: Maquetar la landing (misión, visión, servicios) | D13: 3 | E13: =D13 | F13: 1.4 | G13: Sí | H13: 2.2, 2.5 | I13: B | J13: 6 | K13: 6 | L13: =K13+E13 | M13: =K13-J13 | N13: ="S"&(INT(K13/Resumen!$C$5)+1)&"–S"&MAX(INT(K13/Resumen!$C$5)+1,ROUNDUP(L13/Resumen!$C$5,0)) | O13: Hecho | P13: Propuesta | Q13: ga-diseno-a-codigo
A14: 2.2 | B14: 2. Landing y autenticación | C14: Maquetar /ingresar y /ingresar/codigo | D14: 2 | E14: =D14 | F14: 1.4 | G14: Sí | H14: 2.1 | I14: A | J14: 6 | K14: 6 | L14: =K14+E14 | M14: =K14-J14 | N14: ="S"&(INT(K14/Resumen!$C$5)+1)&"–S"&MAX(INT(K14/Resumen!$C$5)+1,ROUNDUP(L14/Resumen!$C$5,0)) | O14: Hecho | P14: Propuesta | Q14: ga-diseno-a-codigo
A15: 2.3 | B15: 2. Landing y autenticación | C15: Maquetar /afiliacion y /afiliacion/enviada | D15: 2 | E15: =D15 | F15: 1.4 | G15: Sí | H15: 4.1 | I15: A | J15: 6 | K15: 20 | L15: =K15+E15 | M15: =K15-J15 | N15: ="S"&(INT(K15/Resumen!$C$5)+1)&"–S"&MAX(INT(K15/Resumen!$C$5)+1,ROUNDUP(L15/Resumen!$C$5,0)) | O15: Hecho | P15: Agregado | Q15: ga-diseno-a-codigo
A16: 2.4 | B16: 2. Landing y autenticación | C16: SMTP propio con Resend y plantilla del código OTP en Supabase | D16: 2 | E16: =D16 | F16: 1.3 | G16: Sí | H16: 1.4 | I16: B | J16: 1 | K16: 4 | L16: =K16+E16 | M16: =K16-J16 | N16: ="S"&(INT(K16/Resumen!$C$5)+1)&"–S"&MAX(INT(K16/Resumen!$C$5)+1,ROUNDUP(L16/Resumen!$C$5,0)) | O16: Hecho | P16: Agregado | Q16: Yo (panel Supabase)
... A39: 4.3 | B39: 4. Panel de administración | C39: Correo al asociado al resolver y estado actualizado en su pantalla | D39: 2 | E39: =D39 | F39: 4.2, 2.4 | G39: Sí | H39: 4.13, 2.12 | I39: B | J39: 49 | K39: 49 | L39: =K39+E39 | M39: =K39-J39 | N39: ="S"&(INT(K39/Resumen!$C$5)+1)&"–S"&MAX(INT(K39/Resumen!$C$5)+1,ROUNDUP(L39/Resumen!$C$5,0)) | O39: Hecho | P39: Propuesta | Q39: ga-funcionalidad-botones
A40: 4.4 | B40: 4. Panel de administración | C40: Importar asociados desde Excel (con correos reales) | D40: 4 | E40: =D40 | F40: 1.2 | G40: Sí | H40: 2.16, 6.3 | I40: B | J40: 4 | K40: 91 | L40: =K40+E40 | M40: =K40-J40 | N40: ="S"&(INT(K40/Resumen!$C$5)+1)&"–S"&MAX(INT(K40/Resumen!$C$5)+1,ROUNDUP(L40/Resumen!$C$5,0)) | O40: Hecho | P40: Agregado | Q40: ga-funcionalidad-botones | R40: Cancelada: decisión de la cooperativa 2026-09-24, no habrá importación de Excel de asociados.
A41: 4.5 | B41: 4. Panel de administración | C41: Aprobar afiliaciones en /admin: crear el usuario y enviar el correo «Ingreso aceptado» (Resend, ga-ingreso-aceptado) | D41: 3 | E41: =D41 | F41: 4.1, 2.9 | G41: Sí | H41: 2.12 | I41: B | J41: 43 | K41: 51 | L41: =K41+E41 | M41: =K41-J41 | N41: ="S"&(INT(K41/Resumen!$C$5)+1)&"–S"&MAX(INT(K41/Resumen!$C$5)+1,ROUNDUP(L41/Resumen!$C$5,0)) | O41: Hecho | P41: Agregado | Q41: ga-funcionalidad-botones
A42: 4.6 | B42: 4. Panel de administración | C42: Rol asesor: pantalla /asesor (mis clientes) y /asesor/demo (cuenta de demostración) | D42: 3 | E42: =D42 | F42: 1.5 | G42: Sí | H42: 3.10 | I42: B | J42: 18 | K42: 30 | L42: =K42+E42 | M42: =K42-J42 | N42: ="S"&(INT(K42/Resumen!$C$5)+1)&"–S"&MAX(INT(K42/Resumen!$C$5)+1,ROUNDUP(L42/Resumen!$C$5,0)) | O42: Hecho | P42: Agregado | Q42: ga-funcionalidad-botones
A43: 4.7 | B43: 4. Panel de administración | C43: Dashboard de clientes en /admin: métricas (asociados por grado/institución, afiliaciones y créditos pendientes, montos del mes, inscritos al sorteo), lista con buscador/filtros, detalle de cliente y reasignar asesor | D43: 4 | E43: =D43 | F43: 4.1, 4.6 | G43: Sí | H43: 4.17, 5.19 | I43: A | J43: 33 | K43: 85 | L43: =K43+E43 | M43: =K43-J43 | N43: ="S"&(INT(K43/Resumen!$C$5)+1)&"–S"&MAX(INT(K43/Resumen!$C$5)+1,ROUNDUP(L43/Resumen!$C$5,0)) | O43: Hecho | P43: Agregado | Q43: ga-funcionalidad-botones (antes Carlos Pardo)
A44: 4.8 | B44: 4. Panel de administración | C44: Dashboard del asesor en /asesor: métricas de sus clientes (por estado, créditos pendientes, afiliaciones referidas en el mes) y detalle de cliente sin celular, correo, Nequi ni fotos | D44: 3 | E44: =D44 | F44: 4.6 | G44: Sí | H44: 5.18, 6.28, 6.35 | I44: B | J44: 33 | K44: 117 | L44: =K44+E44 | M44: =K44-J44 | N44: ="S"&(INT(K44/Resumen!$C$5)+1)&"–S"&MAX(INT(K44/Resumen!$C$5)+1,ROUNDUP(L44/Resumen!$C$5,0)) | O44: Hecho | P44: Agregado | Q44: ga-funcionalidad-botones (antes Carlos Pardo)
A45: 4.9 | B45: 4. Panel de administración | C45: Cuenta de demostración para administradores en /admin/demo (pestaña «Demostración»): reutiliza la cuenta fantasma de /asesor/demo, un asesor no puede entrar | D45: 2 | E45: =D45 | F45: 4.1, 4.6 | G45: Sí | H45: 3.2 | I45: B | J45: 33 | K45: 128 | L45: =K45+E45 | M45: =K45-J45 | N45: ="S"&(INT(K45/Resumen!$C$5)+1)&"–S"&MAX(INT(K45/Resumen!$C$5)+1,ROUNDUP(L45/Resumen!$C$5,0)) | O45: Hecho | P45: Agregado | Q45: sesión principal
A46: 4.10 | B46: 4. Panel de administración | C46: Rediseño C+ del asesor (/asesor y /asesor/demo) | D46: 2 | E46: =D46 | F46: 4.6, 1.7 | G46: Sí | H46: 1.6 | I46: A | J46: 33 | K46: 33 | L46: =K46+E46 | M46: =K46-J46 | N46: ="S"&(INT(K46/Resumen!$C$5)+1)&"–S"&MAX(INT(K46/Resumen!$C$5)+1,ROUNDUP(L46/Resumen!$C$5,0)) | O46: Hecho | P46: Agregado | Q46: ga-disenador-lienzo + ga-diseno-a-codigo
A47: 4.11 | B47: 4. Panel de administración | C47: Rediseño C+ del admin (incluye la vista en celular) | D47: 3 | E47: =D47 | F47: 4.1, 1.7 | G47: Sí | H47: 2.15 | I47: A | J47: 24 | K47: 24 | L47: =K47+E47 | M47: =K47-J47 | N47: ="S"&(INT(K47/Resumen!$C$5)+1)&"–S"&MAX(INT(K47/Resumen!$C$5)+1,ROUNDUP(L47/Resumen!$C$5,0)) | O47: Hecho | P47: Agregado | Q47: ga-disenador-lienzo + ga-diseno-a-codigo
A48: 5.1 | B48: 5. Convenios y pulido | C48: Sección de convenios (en /cuenta y landing) | D48: 2 | E48: =D48 | F48: 3.4 | G48: Sí | H48: 4.20, 5.2 | I48: B | J48: 30 | K48: 63 | L48: =K48+E48 | M48: =K48-J48 | N48: ="S"&(INT(K48/Resumen!$C$5)+1)&"–S"&MAX(INT(K48/Resumen!$C$5)+1,ROUNDUP(L48/Resumen!$C$5,0)) | O48: Hecho | P48: Propuesta | Q48: ga-diseno-a-codigo
A49: 5.2 | B49: 5. Convenios y pulido | C49: Diseño responsive celular / tableta / PC | D49: 3 | E49: =D49 | F49: 2.1, 2.2, 2.3, 3.4 | G49: Sí | H49: 5.1, 3.6 | I49: A | J49: 30 | K49: 64 | L49: =K49+E49 | M49: =K49-J49 | N49: ="S"&(INT(K49/Resumen!$C$5)+1)&"–S"&MAX(INT(K49/Resumen!$C$5)+1,ROUNDUP(L49/Resumen!$C$5,0)) | O49: Hecho | P49: Propuesta | Q49: ga-verificador-responsive
A50: 5.3 | B50: 5. Convenios y pulido | C50: Cambiar datos de ejemplo por reales (config.ts, mock.ts, fotos, cifras) | D50: 2 | E50: =D50 | F50: 5.2 | G50: Sí | H50: 6.42 | I50: B | J50: 134 | K50: 139 | L50: =K50+E50 | M50: =K50-J50 | N50: ="S"&(INT(K50/Resumen!$C$5)+1)&"–S"&MAX(INT(K50/Resumen!$C$5)+1,ROUNDUP(L50/Resumen!$C$5,0)) | O50: Bloqueado | P50: Propuesta | Q50: ga-diseno-a-codigo | R50: Falta de la cooperativa: fotos, cifras, testimonios y fotos de las sedes.
A51: 5.4 | B51: 5. Convenios y pulido | C51: Página de política de datos (/politica-de-datos) | D51: 1 | E51: =D51 | F51: 5.2 | G51: Sí | H51: 5.5 | I51: A | J51: 67 | K51: 79 | L51: =K51+E51 | M51: =K51-J51 | N51: ="S"&(INT(K51/Resumen!$C$5)+1)&"–S"&MAX(INT(K51/Resumen!$C$5)+1,ROUNDUP(L51/Resumen!$C$5,0)) | O51: Hecho | P51: Agregado | Q51: ga-diseno-a-codigo
A52: 5.5 | B52: 5. Convenios y pulido | C52: Borrar las rutas viejas /login y /dashboard | D52: 1 | E52: =D52 | F52: 3.7, 2.7 | G52: Sí | H52: 5.4 | I52: B | J52: 62 | K52: 79 | L52: =K52+E52 | M52: =K52-J52 | N52: ="S"&(INT(K52/Resumen!$C$5)+1)&"–S"&MAX(INT(K52/Resumen!$C$5)+1,ROUNDUP(L52/Resumen!$C$5,0)) | O52: Hecho | P52: Agregado | Q52: ga-funcionalidad-botones
A53: 5.6 | B53: 5. Convenios y pulido | C53: Revisar el diseño de /cuenta/solicitar (pantalla sin maqueta; selector 50/100 ahora son radios) | D53: 1 | E53: =D53 | F53: 3.7 | G53: Sí | H53: 4.20 | I53: B | J53: 62 | K53: 62 | L53: =K53+E53 | M53: =K53-J53 | N53: ="S"&(INT(K53/Resumen!$C$5)+1)&"–S"&MAX(INT(K53/Resumen!$C$5)+1,ROUNDUP(L53/Resumen!$C$5,0)) | O53: Hecho | P53: Agregado | Q53: ga-diseno-a-codigo
A54: 5.7 | B54: 5. Convenios y pulido | C54: Logo horizontal con las letras oficiales (SVG) y espacios de foto de marca en la landing (EspacioFoto) | D54: 2 | E54: =D54 | F54: 2.1 | G54: Sí | H54: 6.33, 6.32 | I54: B | J54: 9 | K54: 98 | L54: =K54+E54 | M54: =K54-J54 | N54: ="S"&(INT(K54/Resumen!$C$5)+1)&"–S"&MAX(INT(K54/Resumen!$C$5)+1,ROUNDUP(L54/Resumen!$C$5,0)) | O54: Hecho | P54: Agregado | Q54: ga-diseno-a-codigo
A55: 5.8 | B55: 5. Convenios y pulido | C55: Corregir scroll horizontal: headers con logo (320 px) y formulario de /ingresar y /ingresar/codigo (1024–1075 px) | D55: 1 | E55: =D55 | F55: 5.2, 5.7 | G55: Sí | H55: 4.25 | I55: A | J55: 100 | K55: 103 | L55: =K55+E55 | M55: =K55-J55 | N55: ="S"&(INT(K55/Resumen!$C$5)+1)&"–S"&MAX(INT(K55/Resumen!$C$5)+1,ROUNDUP(L55/Resumen!$C$5,0)) | O55: Hecho | P55: Agregado | Q55: ga-diseno-a-codigo + ga-verificador-responsive
A56: 5.9 | B56: 5. Convenios y pulido | C56: Convenios administrables desde /admin (crear, editar, ocultar y ordenar, logo en Storage); landing y /cuenta leen de la tabla convenios | D56: 3 | E56: =D56 | F56: 4.1, 5.1 | G56: Sí | H56: 5.15 | I56: B | J56: 65 | K56: 80 | L56: =K56+E56 | M56: =K56-J56 | N56: ="S"&(INT(K56/Resumen!$C$5)+1)&"–S"&MAX(INT(K56/Resumen!$C$5)+1,ROUNDUP(L56/Resumen!$C$5,0)) | O56: Hecho | P56: Agregado | Q56: ga-funcionalidad-botones + ga-auditor-supabase
A57: 5.10 | B57: 5. Convenios y pulido | C57: Ley 1581: borrado automático de fotos de afiliaciones rechazadas tras X días (pg_cron o cron de Vercel) y motivo de rechazo en /admin (columna y campo) | D57: 2 | E57: =D57 | F57: 2.12, 4.1 | G57: Sí | H57: 4.21 | I57: B | J57: 54 | K57: 124 | L57: =K57+E57 | M57: =K57-J57 | N57: ="S"&(INT(K57/Resumen!$C$5)+1)&"–S"&MAX(INT(K57/Resumen!$C$5)+1,ROUNDUP(L57/Resumen!$C$5,0)) | O57: Hecho | P57: Agregado | Q57: ga-funcionalidad-botones + ga-auditor-supabase (antes Carlos Pardo)
A58: 6.1 | B58: 6. Pruebas y lanzamiento | C58: Pruebas de las nuevas Server Actions (login, afiliación, crédito, admin) | D58: 3 | E58: =D58 | F58: 2.10, 3.6, 4.3, 4.5 | G58: Sí | H58: 5.12, 4.23 | I58: B | J58: 67 | K58: 72 | L58: =K58+E58 | M58: =K58-J58 | N58: ="S"&(INT(K58/Resumen!$C$5)+1)&"–S"&MAX(INT(K58/Resumen!$C$5)+1,ROUNDUP(L58/Resumen!$C$5,0)) | O58: Hecho | P58: Propuesta | Q58: ga-escritor-tests
A59: 6.2 | B59: 6. Pruebas y lanzamiento | C59: Revisión de seguridad completa | D59: 2 | E59: =D59 | F59: 2.10, 3.6, 4.3, 4.5, 2.12, 3.9, 4.6 | G59: Sí | H59: 5.16, 6.15 | I59: A | J59: 71 | K59: 101 | L59: =K59+E59 | M59: =K59-J59 | N59: ="S"&(INT(K59/Resumen!$C$5)+1)&"–S"&MAX(INT(K59/Resumen!$C$5)+1,ROUNDUP(L59/Resumen!$C$5,0)) | O59: Hecho | P59: Propuesta | Q59: ga-revisor-seguridad
A60: 6.3 | B60: 6. Pruebas y lanzamiento | C60: QA de punta a punta y verificación responsive | D60: 3 | E60: =D60 | F60: 6.1, 5.5, 2.8, 5.4, 2.11, 5.6, 1.6, 2.12, 3.9, 4.6 | G60: Sí | H60: 4.4, 6.26 | I60: A | J60: 85 | K60: 93 | L60: =K60+E60 | M60: =K60-J60 | N60: ="S"&(INT(K60/Resumen!$C$5)+1)&"–S"&MAX(INT(K60/Resumen!$C$5)+1,ROUNDUP(L60/Resumen!$C$5,0)) | O60: Hecho | P60: Propuesta | Q60: ga-verificador-qa + ga-verificador-responsive
A61: 6.4 | B61: 6. Pruebas y lanzamiento | C61: Registrar dominio (5 años) y protección de dominio | D61: 1 | E61: =D61 | F61: — | G61: Sí | H61: 3.4 | I61: A | J61: 0 | K61: 29 | L61: =K61+E61 | M61: =K61-J61 | N61: ="S"&(INT(K61/Resumen!$C$5)+1)&"–S"&MAX(INT(K61/Resumen!$C$5)+1,ROUNDUP(L61/Resumen!$C$5,0)) | O61: Hecho | P61: Propuesta | Q61: Yo + cooperativa
A62: 6.5 | B62: 6. Pruebas y lanzamiento | C62: Subir a GitHub y desplegar en Vercel (producción) | D62: 2 | E62: =D62 | F62: 6.2, 6.3, 6.4, 2.4, 6.8, 6.9, 6.10, 6.13 | G62: No (usa las 2 filas) | H62: — | I62: A+B | J62: 107 | K62: 111 | L62: =K62+E62 | M62: =K62-J62 | N62: ="S"&(INT(K62/Resumen!$C$5)+1)&"–S"&MAX(INT(K62/Resumen!$C$5)+1,ROUNDUP(L62/Resumen!$C$5,0)) | O62: Hecho | P62: Propuesta | Q62: Yo
... A129: 6.42 | B129: 6. Pruebas y lanzamiento | C129: Revisión de seguridad y QA de Editar datos del asociado, Afiliación sin repetidos, Pausa de cuenta, Avisos, botón de WhatsApp y selfie | D129: 3 | E129: =D129 | F129: 4.23, 2.16, 4.24, 4.25, 3.11, 2.17, 4.26, 4.27 | G129: Sí | H129: 5.3 | I129: A | J129: 138 | K129: 139 | L129: =K129+E129 | M129: =K129-J129 | N129: ="S"&(INT(K129/Resumen!$C$5)+1)&"–S"&MAX(INT(K129/Resumen!$C$5)+1,ROUNDUP(L129/Resumen!$C$5,0)) | O129: En curso | P129: Agregado | Q129: ga-revisor-seguridad
...

Sheet Gantt
A1: Diagrama de Gantt optimizado — 2 filas, cola infinita
A2: El número al inicio de cada barra es el peso (1–5). Verde = Fila A, azul = Fila B, morado = usa las 2 filas, gris verdoso = hecho, ámbar = bloqueado por la cooperativa. Columna roja = HOY.
H4: Semana 1 | R4: Semana 2 | AB4: Semana 3 | AL4: Semana 4 | AV4: Semana 5 | BF4: Semana 6 | BP4: Semana 7 | BZ4: Semana 8 | CJ4: Semana 9 | CT4: Semana 10 | DD4: Semana 11 | DN4: Semana 12 | DX4: Semana 13 | EH4: Semana 14 | ER4: Semana 15
A5: ID | B5: Actividad | C5: Peso | D5: Fila | E5: Inicio | F5: Fin | G5: Estado | H5: 1 | I5: 2 | J5: 3 | K5: 4 | L5: 5 | M5: 6 | N5: 7 | O5: 8 | P5: 9 | Q5: 10 | R5: 11 | S5: 12 | T5: 13 | U5: 14 | V5: 15 | W5: 16 | X5: 17 | Y5: 18 | Z5: 19 | AA5: 20 | AB5: 21 | AC5: 22 | AD5: 23 | AE5: 24 | AF5: 25 | AG5: 26 | AH5: 27 | AI5: 28 | AJ5: 29 | AK5: 30 | AL5: 31 | AM5: 32 | AN5: 33 | AO5: 34 | AP5: 35 | AQ5: 36 | AR5: 37 | AS5: 38 | AT5: 39 | AU5: 40 | AV5: 41 | AW5: 42 | AX5: 43 | AY5: 44 | AZ5: 45 | BA5: 46 | BB5: 47 | BC5: 48 | BD5: 49 | BE5: 50 | BF5: 51 | BG5: 52 | BH5: 53 | BI5: 54 | BJ5: 55 | BK5: 56 | BL5: 57 | BM5: 58 | BN5: 59 | BO5: 60 | BP5: 61 | BQ5: 62 | BR5: 63 | BS5: 64 | BT5: 65 | BU5: 66 | BV5: 67 | BW5: 68 | BX5: 69 | BY5: 70 | BZ5: 71 | CA5: 72 | CB5: 73 | CC5: 74 | CD5: 75 | CE5: 76 | CF5: 77 | CG5: 78 | CH5: 79 | CI5: 80 | CJ5: 81 | CK5: 82 | CL5: 83 | CM5: 84 | CN5: 85 | CO5: 86 | CP5: 87 | CQ5: 88 | CR5: 89 | CS5: 90 | CT5: 91 | CU5: 92 | CV5: 93 | CW5: 94 | CX5: 95 | CY5: 96 | CZ5: 97 | DA5: 98 | DB5: 99 | DC5: 100 | DD5: 101 | DE5: 102 | DF5: 103 | DG5: 104 | DH5: 105 | DI5: 106 | DJ5: 107 | DK5: 108 | DL5: 109 | DM5: 110 | DN5: 111 | DO5: 112 | DP5: 113 | DQ5: 114 | DR5: 115 | DS5: 116 | DT5: 117 | DU5: 118 | DV5: 119 | DW5: 120 | DX5: 121 | DY5: 122 | DZ5: 123 | EA5: 124 | EB5: 125 | EC5: 126 | ED5: 127 | EE5: 128 | EF5: 129 | EG5: 130 | EH5: 131 | EI5: 132 | EJ5: 133 | EK5: 134 | EL5: 135 | EM5: 136 | EN5: 137 | EO5: 138 | EP5: 139 | EQ5: 140 | ER5: 141 | ES5: 142 | ET5: 143 | EU5: 144 | EV5: 145 | EW5: 146 | EX5: 147 | EY5: 148 | EZ5: 149 | FA5: 150
A6: Fila A — tarea en curso | H6: =IF(SUMPRODUCT(((Plan!$I$5:$I$129="A")+(Plan!$I$5:$I$129="A+B"))*(Plan!$K$5:$K$129<H$5)*(Plan!$L$5:$L$129>=H$5))=0,"",INDEX(Plan!$A$5:$A$129,SUMPRODUCT(((Plan!$I$5:$I$129="A")+(Plan!$I$5:$I$129="A+B"))*(Plan!$K$5:$K$129<H$5)*(Plan!$L$5:$L$129>=H$5)*(ROW(Plan!$A$5:$A$129)-4)))) | I6: =IF(SUMPRODUCT(((Plan!$I$5:$I$129="A")+(Plan!$I$5:$I$129="A+B"))*(Plan!$K$5:$K$129<I$5)*(Plan!$L$5:$L$129>=I$5))=0,"",INDEX(Plan!$A$5:$A$129,SUMPRODUCT(((Plan!$I$5:$I$129="A")+(Plan!$I$5:$I$129="A+B"))*(Plan!$K$5:$K$129<I$5)*(Plan!$L$5:$L$129>=I$5)*(ROW(Plan!$A$5:$A$129)-4)))) | J6: =IF(SUMPRODUCT(((Plan!$I$5:$I$129="A")+(Plan!$I$5:$I$129="A+B"))*(Plan!$K$5:$K$129<J$5)*(Plan!$L$5:$L$129>=J$5))=0,"",INDEX(Plan!$A$5:$A$129,SUMPRODUCT(((Plan!$I$5:$I$129="A")+(Plan!$I$5:$I$129="A+B"))*(Plan!$K$5:$K$129<J$5)*(Plan!$L$5:$L$129>=J$5)*(ROW(Plan!$A$5:$A$129)-4)))) | K6: =IF(SUMPRODUCT(((Plan!$I$5:$I$129="A")+(Plan!$I$5:$I$129="A+B"))*(Plan!$K$5:$K$129<K$5)*(Plan!$L$5:$L$129>=K$5))=0,"",INDEX(Plan!$A$5:$A$129,SUMPRODUCT(((Plan!$I$5:$I$129="A")+(Plan!$I$5:$I$129="A+B"))*(Plan!$K$5:$K$129<K$5)*(Plan!$L$5:$L$129>=K$5)*(ROW(Plan!$A$5:$A$129)-4)))) | L6: =IF(SUMPRODUCT(((Plan!$I$5:$I$129="A")+(Plan!$I$5:$I$129="A+B"))*(Plan!$K$5:$K$129<L$5)*(Plan!$L$5:$L$129>=L$5))=0,"",INDEX(Plan!$A$5:$A$129,SUMPRODUCT(((Plan!$I$5:$I$129="A")+(Plan!$I$5:$I$129="A+B"))*(Plan!$K$5:$K$129<L$5)*(Plan!$L$5:$L$129>=L$5)*(ROW(Plan!$A$5:$A$129)-4)))) | M6: =IF(SUMPRODUCT(((Plan!$I$5:$I$129="A")+(Plan!$I$5:$I$129="A+B"))*(Plan!$K$5:$K$129<M$5)*(Plan!$L$5:$L$129>=M$5))=0,"",INDEX(Plan!$A$5:$A$129,SUMPRODUCT(((Plan!$I$5:$I$129="A")+(Plan!$I$5:$I$129="A+B"))*(Plan!$K$5:$K$129<M$5)*(Plan!$L$5:$L$129>=M$5)*(ROW(Plan!$A$5:$A$129)-4)))) | N6: =IF(SUMPRODUCT(((Plan!$I$5:$I$129="A")+(Plan!$I$5:$I$129="A+B"))*(Plan!$K$5:$K$129<N$5)*(Plan!$L$5:$L$129>=N$5))=0,"",INDEX(Plan!$A$5:$A$129,SUMPRODUCT(((Plan!$I$5:$I$129="A")+(Plan!$I$5:$I$129="A+B"))*(Plan!$K$5:$K$129<N$5)*(Plan!$L$5:$L$129>=N$5)*(ROW(Plan!$A$5:$A$129)-4)))) | O6: =IF(SUMPRODUCT(((Plan!$I$5:$I$129="A")+(Plan!$I$5:$I$129="A+B"))*(Plan!$K$5:$K$129<O$5)*(Plan!$L$5:$L$129>=O$5))=0,"",INDEX(Plan!$A$5:$A$129,SUMPRODUCT(((Plan!$I$5:$I$129="A")+(Plan!$I$5:$I$129="A+B"))*(Plan!$K$5:$K$129<O$5)*(Plan!$L$5:$L$129>=O$5)*(ROW(Plan!$A$5:$A$129)-4)))) | ... FA6: =IF(SUMPRODUCT(((Plan!$I$5:$I$129="A")+(Plan!$I$5:$I$129="A+B"))*(Plan!$K$5:$K$129<FA$5)*(Plan!$L$5:$L$129>=FA$5))=0,"",INDEX(Plan!$A$5:$A$129,SUMPRODUCT(((Plan!$I$5:$I$129="A")+(Plan!$I$5:$I$129="A+B"))*(Plan!$K$5:$K$129<FA$5)*(Plan!$L$5:$L$129>=FA$5)*(ROW(Plan!$A$5:$A$129)-4))))
A7: Fila B — tarea en curso | H7: =IF(SUMPRODUCT(((Plan!$I$5:$I$129="B")+(Plan!$I$5:$I$129="A+B"))*(Plan!$K$5:$K$129<H$5)*(Plan!$L$5:$L$129>=H$5))=0,"",INDEX(Plan!$A$5:$A$129,SUMPRODUCT(((Plan!$I$5:$I$129="B")+(Plan!$I$5:$I$129="A+B"))*(Plan!$K$5:$K$129<H$5)*(Plan!$L$5:$L$129>=H$5)*(ROW(Plan!$A$5:$A$129)-4)))) | I7: =IF(SUMPRODUCT(((Plan!$I$5:$I$129="B")+(Plan!$I$5:$I$129="A+B"))*(Plan!$K$5:$K$129<I$5)*(Plan!$L$5:$L$129>=I$5))=0,"",INDEX(Plan!$A$5:$A$129,SUMPRODUCT(((Plan!$I$5:$I$129="B")+(Plan!$I$5:$I$129="A+B"))*(Plan!$K$5:$K$129<I$5)*(Plan!$L$5:$L$129>=I$5)*(ROW(Plan!$A$5:$A$129)-4)))) | J7: =IF(SUMPRODUCT(((Plan!$I$5:$I$129="B")+(Plan!$I$5:$I$129="A+B"))*(Plan!$K$5:$K$129<J$5)*(Plan!$L$5:$L$129>=J$5))=0,"",INDEX(Plan!$A$5:$A$129,SUMPRODUCT(((Plan!$I$5:$I$129="B")+(Plan!$I$5:$I$129="A+B"))*(Plan!$K$5:$K$129<J$5)*(Plan!$L$5:$L$129>=J$5)*(ROW(Plan!$A$5:$A$129)-4)))) | K7: =IF(SUMPRODUCT(((Plan!$I$5:$I$129="B")+(Plan!$I$5:$I$129="A+B"))*(Plan!$K$5:$K$129<K$5)*(Plan!$L$5:$L$129>=K$5))=0,"",INDEX(Plan!$A$5:$A$129,SUMPRODUCT(((Plan!$I$5:$I$129="B")+(Plan!$I$5:$I$129="A+B"))*(Plan!$K$5:$K$129<K$5)*(Plan!$L$5:$L$129>=K$5)*(ROW(Plan!$A$5:$A$129)-4)))) | L7: =IF(SUMPRODUCT(((Plan!$I$5:$I$129="B")+(Plan!$I$5:$I$129="A+B"))*(Plan!$K$5:$K$129<L$5)*(Plan!$L$5:$L$129>=L$5))=0,"",INDEX(Plan!$A$5:$A$129,SUMPRODUCT(((Plan!$I$5:$I$129="B")+(Plan!$I$5:$I$129="A+B"))*(Plan!$K$5:$K$129<L$5)*(Plan!$L$5:$L$129>=L$5)*(ROW(Plan!$A$5:$A$129)-4)))) | M7: =IF(SUMPRODUCT(((Plan!$I$5:$I$129="B")+(Plan!$I$5:$I$129="A+B"))*(Plan!$K$5:$K$129<M$5)*(Plan!$L$5:$L$129>=M$5))=0,"",INDEX(Plan!$A$5:$A$129,SUMPRODUCT(((Plan!$I$5:$I$129="B")+(Plan!$I$5:$I$129="A+B"))*(Plan!$K$5:$K$129<M$5)*(Plan!$L$5:$L$129>=M$5)*(ROW(Plan!$A$5:$A$129)-4)))) | N7: =IF(SUMPRODUCT(((Plan!$I$5:$I$129="B")+(Plan!$I$5:$I$129="A+B"))*(Plan!$K$5:$K$129<N$5)*(Plan!$L$5:$L$129>=N$5))=0,"",INDEX(Plan!$A$5:$A$129,SUMPRODUCT(((Plan!$I$5:$I$129="B")+(Plan!$I$5:$I$129="A+B"))*(Plan!$K$5:$K$129<N$5)*(Plan!$L$5:$L$129>=N$5)*(ROW(Plan!$A$5:$A$129)-4)))) | O7: =IF(SUMPRODUCT(((Plan!$I$5:$I$129="B")+(Plan!$I$5:$I$129="A+B"))*(Plan!$K$5:$K$129<O$5)*(Plan!$L$5:$L$129>=O$5))=0,"",INDEX(Plan!$A$5:$A$129,SUMPRODUCT(((Plan!$I$5:$I$129="B")+(Plan!$I$5:$I$129="A+B"))*(Plan!$K$5:$K$129<O$5)*(Plan!$L$5:$L$129>=O$5)*(ROW(Plan!$A$5:$A$129)-4)))) | ... FA7: =IF(SUMPRODUCT(((Plan!$I$5:$I$129="B")+(Plan!$I$5:$I$129="A+B"))*(Plan!$K$5:$K$129<FA$5)*(Plan!$L$5:$L$129>=FA$5))=0,"",INDEX(Plan!$A$5:$A$129,SUMPRODUCT(((Plan!$I$5:$I$129="B")+(Plan!$I$5:$I$129="A+B"))*(Plan!$K$5:$K$129<FA$5)*(Plan!$L$5:$L$129>=FA$5)*(ROW(Plan!$A$5:$A$129)-4))))
A9: Fase 1. Diseño y arquitectura | E9: =SUMPRODUCT(MIN((Plan!$B$5:$B$129="1. Diseño y arquitectura")*Plan!$K$5:$K$129+(Plan!$B$5:$B$129<>"1. Diseño y arquitectura")*1E9)) | F9: =SUMPRODUCT(MAX((Plan!$B$5:$B$129="1. Diseño y arquitectura")*Plan!$L$5:$L$129)) | G9: =Resumen!E29
A10: =Plan!A5 | B10: =Plan!C5 | C10: =Plan!D5 | D10: =Plan!I5 | E10: =Plan!K5 | F10: =Plan!L5 | G10: =Plan!O5 | H10: =IF(AND(H$5>$E10,H$5<=$F10),IF(H$5=$E10+1,$C10,""),"") | I10: =IF(AND(I$5>$E10,I$5<=$F10),IF(I$5=$E10+1,$C10,""),"") | J10: =IF(AND(J$5>$E10,J$5<=$F10),IF(J$5=$E10+1,$C10,""),"") | K10: =IF(AND(K$5>$E10,K$5<=$F10),IF(K$5=$E10+1,$C10,""),"") | L10: =IF(AND(L$5>$E10,L$5<=$F10),IF(L$5=$E10+1,$C10,""),"") | M10: =IF(AND(M$5>$E10,M$5<=$F10),IF(M$5=$E10+1,$C10,""),"") | N10: =IF(AND(N$5>$E10,N$5<=$F10),IF(N$5=$E10+1,$C10,""),"") | O10: =IF(AND(O$5>$E10,O$5<=$F10),IF(O$5=$E10+1,$C10,""),"") | ... FA10: =IF(AND(FA$5>$E10,FA$5<=$F10),IF(FA$5=$E10+1,$C10,""),"")
A11: =Plan!A6 | B11: =Plan!C6 | C11: =Plan!D6 | D11: =Plan!I6 | E11: =Plan!K6 | F11: =Plan!L6 | G11: =Plan!O6 | H11: =IF(AND(H$5>$E11,H$5<=$F11),IF(H$5=$E11+1,$C11,""),"") | I11: =IF(AND(I$5>$E11,I$5<=$F11),IF(I$5=$E11+1,$C11,""),"") | J11: =IF(AND(J$5>$E11,J$5<=$F11),IF(J$5=$E11+1,$C11,""),"") | K11: =IF(AND(K$5>$E11,K$5<=$F11),IF(K$5=$E11+1,$C11,""),"") | L11: =IF(AND(L$5>$E11,L$5<=$F11),IF(L$5=$E11+1,$C11,""),"") | M11: =IF(AND(M$5>$E11,M$5<=$F11),IF(M$5=$E11+1,$C11,""),"") | N11: =IF(AND(N$5>$E11,N$5<=$F11),IF(N$5=$E11+1,$C11,""),"") | O11: =IF(AND(O$5>$E11,O$5<=$F11),IF(O$5=$E11+1,$C11,""),"") | ... FA11: =IF(AND(FA$5>$E11,FA$5<=$F11),IF(FA$5=$E11+1,$C11,""),"")
A12: =Plan!A7 | B12: =Plan!C7 | C12: =Plan!D7 | D12: =Plan!I7 | E12: =Plan!K7 | F12: =Plan!L7 | G12: =Plan!O7 | H12: =IF(AND(H$5>$E12,H$5<=$F12),IF(H$5=$E12+1,$C12,""),"") | I12: =IF(AND(I$5>$E12,I$5<=$F12),IF(I$5=$E12+1,$C12,""),"") | J12: =IF(AND(J$5>$E12,J$5<=$F12),IF(J$5=$E12+1,$C12,""),"") | K12: =IF(AND(K$5>$E12,K$5<=$F12),IF(K$5=$E12+1,$C12,""),"") | L12: =IF(AND(L$5>$E12,L$5<=$F12),IF(L$5=$E12+1,$C12,""),"") | M12: =IF(AND(M$5>$E12,M$5<=$F12),IF(M$5=$E12+1,$C12,""),"") | N12: =IF(AND(N$5>$E12,N$5<=$F12),IF(N$5=$E12+1,$C12,""),"") | O12: =IF(AND(O$5>$E12,O$5<=$F12),IF(O$5=$E12+1,$C12,""),"") | ... FA12: =IF(AND(FA$5>$E12,FA$5<=$F12),IF(FA$5=$E12+1,$C12,""),"")
A13: =Plan!A8 | B13: =Plan!C8 | C13: =Plan!D8 | D13: =Plan!I8 | E13: =Plan!K8 | F13: =Plan!L8 | G13: =Plan!O8 | H13: =IF(AND(H$5>$E13,H$5<=$F13),IF(H$5=$E13+1,$C13,""),"") | I13: =IF(AND(I$5>$E13,I$5<=$F13),IF(I$5=$E13+1,$C13,""),"") | J13: =IF(AND(J$5>$E13,J$5<=$F13),IF(J$5=$E13+1,$C13,""),"") | K13: =IF(AND(K$5>$E13,K$5<=$F13),IF(K$5=$E13+1,$C13,""),"") | L13: =IF(AND(L$5>$E13,L$5<=$F13),IF(L$5=$E13+1,$C13,""),"") | M13: =IF(AND(M$5>$E13,M$5<=$F13),IF(M$5=$E13+1,$C13,""),"") | N13: =IF(AND(N$5>$E13,N$5<=$F13),IF(N$5=$E13+1,$C13,""),"") | O13: =IF(AND(O$5>$E13,O$5<=$F13),IF(O$5=$E13+1,$C13,""),"") | ... FA13: =IF(AND(FA$5>$E13,FA$5<=$F13),IF(FA$5=$E13+1,$C13,""),"")
A14: =Plan!A9 | B14: =Plan!C9 | C14: =Plan!D9 | D14: =Plan!I9 | E14: =Plan!K9 | F14: =Plan!L9 | G14: =Plan!O9 | H14: =IF(AND(H$5>$E14,H$5<=$F14),IF(H$5=$E14+1,$C14,""),"") | I14: =IF(AND(I$5>$E14,I$5<=$F14),IF(I$5=$E14+1,$C14,""),"") | J14: =IF(AND(J$5>$E14,J$5<=$F14),IF(J$5=$E14+1,$C14,""),"") | K14: =IF(AND(K$5>$E14,K$5<=$F14),IF(K$5=$E14+1,$C14,""),"") | L14: =IF(AND(L$5>$E14,L$5<=$F14),IF(L$5=$E14+1,$C14,""),"") | M14: =IF(AND(M$5>$E14,M$5<=$F14),IF(M$5=$E14+1,$C14,""),"") | N14: =IF(AND(N$5>$E14,N$5<=$F14),IF(N$5=$E14+1,$C14,""),"") | O14: =IF(AND(O$5>$E14,O$5<=$F14),IF(O$5=$E14+1,$C14,""),"") | ... FA14: =IF(AND(FA$5>$E14,FA$5<=$F14),IF(FA$5=$E14+1,$C14,""),"")
A15: =Plan!A10 | B15: =Plan!C10 | C15: =Plan!D10 | D15: =Plan!I10 | E15: =Plan!K10 | F15: =Plan!L10 | G15: =Plan!O10 | H15: =IF(AND(H$5>$E15,H$5<=$F15),IF(H$5=$E15+1,$C15,""),"") | I15: =IF(AND(I$5>$E15,I$5<=$F15),IF(I$5=$E15+1,$C15,""),"") | J15: =IF(AND(J$5>$E15,J$5<=$F15),IF(J$5=$E15+1,$C15,""),"") | K15: =IF(AND(K$5>$E15,K$5<=$F15),IF(K$5=$E15+1,$C15,""),"") | L15: =IF(AND(L$5>$E15,L$5<=$F15),IF(L$5=$E15+1,$C15,""),"") | M15: =IF(AND(M$5>$E15,M$5<=$F15),IF(M$5=$E15+1,$C15,""),"") | N15: =IF(AND(N$5>$E15,N$5<=$F15),IF(N$5=$E15+1,$C15,""),"") | O15: =IF(AND(O$5>$E15,O$5<=$F15),IF(O$5=$E15+1,$C15,""),"") | ... FA15: =IF(AND(FA$5>$E15,FA$5<=$F15),IF(FA$5=$E15+1,$C15,""),"")
A16: =Plan!A11 | B16: =Plan!C11 | C16: =Plan!D11 | D16: =Plan!I11 | E16: =Plan!K11 | F16: =Plan!L11 | G16: =Plan!O11 | H16: =IF(AND(H$5>$E16,H$5<=$F16),IF(H$5=$E16+1,$C16,""),"") | I16: =IF(AND(I$5>$E16,I$5<=$F16),IF(I$5=$E16+1,$C16,""),"") | J16: =IF(AND(J$5>$E16,J$5<=$F16),IF(J$5=$E16+1,$C16,""),"") | K16: =IF(AND(K$5>$E16,K$5<=$F16),IF(K$5=$E16+1,$C16,""),"") | L16: =IF(AND(L$5>$E16,L$5<=$F16),IF(L$5=$E16+1,$C16,""),"") | M16: =IF(AND(M$5>$E16,M$5<=$F16),IF(M$5=$E16+1,$C16,""),"") | N16: =IF(AND(N$5>$E16,N$5<=$F16),IF(N$5=$E16+1,$C16,""),"") | O16: =IF(AND(O$5>$E16,O$5<=$F16),IF(O$5=$E16+1,$C16,""),"") | ... FA16: =IF(AND(FA$5>$E16,FA$5<=$F16),IF(FA$5=$E16+1,$C16,""),"")
A17: =Plan!A12 | B17: =Plan!C12 | C17: =Plan!D12 | D17: =Plan!I12 | E17: =Plan!K12 | F17: =Plan!L12 | G17: =Plan!O12 | H17: =IF(AND(H$5>$E17,H$5<=$F17),IF(H$5=$E17+1,$C17,""),"") | I17: =IF(AND(I$5>$E17,I$5<=$F17),IF(I$5=$E17+1,$C17,""),"") | J17: =IF(AND(J$5>$E17,J$5<=$F17),IF(J$5=$E17+1,$C17,""),"") | K17: =IF(AND(K$5>$E17,K$5<=$F17),IF(K$5=$E17+1,$C17,""),"") | L17: =IF(AND(L$5>$E17,L$5<=$F17),IF(L$5=$E17+1,$C17,""),"") | M17: =IF(AND(M$5>$E17,M$5<=$F17),IF(M$5=$E17+1,$C17,""),"") | N17: =IF(AND(N$5>$E17,N$5<=$F17),IF(N$5=$E17+1,$C17,""),"") | O17: =IF(AND(O$5>$E17,O$5<=$F17),IF(O$5=$E17+1,$C17,""),"") | ... FA17: =IF(AND(FA$5>$E17,FA$5<=$F17),IF(FA$5=$E17+1,$C17,""),"")
A18: Fase 2. Landing y autenticación | E18: =SUMPRODUCT(MIN((Plan!$B$5:$B$129="2. Landing y autenticación")*Plan!$K$5:$K$129+(Plan!$B$5:$B$129<>"2. Landing y autenticación")*1E9)) | F18: =SUMPRODUCT(MAX((Plan!$B$5:$B$129="2. Landing y autenticación")*Plan!$L$5:$L$129)) | G18: =Resumen!E30
A19: =Plan!A13 | B19: =Plan!C13 | C19: =Plan!D13 | D19: =Plan!I13 | E19: =Plan!K13 | F19: =Plan!L13 | G19: =Plan!O13 | H19: =IF(AND(H$5>$E19,H$5<=$F19),IF(H$5=$E19+1,$C19,""),"") | I19: =IF(AND(I$5>$E19,I$5<=$F19),IF(I$5=$E19+1,$C19,""),"") | J19: =IF(AND(J$5>$E19,J$5<=$F19),IF(J$5=$E19+1,$C19,""),"") | K19: =IF(AND(K$5>$E19,K$5<=$F19),IF(K$5=$E19+1,$C19,""),"") | L19: =IF(AND(L$5>$E19,L$5<=$F19),IF(L$5=$E19+1,$C19,""),"") | M19: =IF(AND(M$5>$E19,M$5<=$F19),IF(M$5=$E19+1,$C19,""),"") | N19: =IF(AND(N$5>$E19,N$5<=$F19),IF(N$5=$E19+1,$C19,""),"") | O19: =IF(AND(O$5>$E19,O$5<=$F19),IF(O$5=$E19+1,$C19,""),"") | ... FA19: =IF(AND(FA$5>$E19,FA$5<=$F19),IF(FA$5=$E19+1,$C19,""),"")
A20: =Plan!A14 | B20: =Plan!C14 | C20: =Plan!D14 | D20: =Plan!I14 | E20: =Plan!K14 | F20: =Plan!L14 | G20: =Plan!O14 | H20: =IF(AND(H$5>$E20,H$5<=$F20),IF(H$5=$E20+1,$C20,""),"") | I20: =IF(AND(I$5>$E20,I$5<=$F20),IF(I$5=$E20+1,$C20,""),"") | J20: =IF(AND(J$5>$E20,J$5<=$F20),IF(J$5=$E20+1,$C20,""),"") | K20: =IF(AND(K$5>$E20,K$5<=$F20),IF(K$5=$E20+1,$C20,""),"") | L20: =IF(AND(L$5>$E20,L$5<=$F20),IF(L$5=$E20+1,$C20,""),"") | M20: =IF(AND(M$5>$E20,M$5<=$F20),IF(M$5=$E20+1,$C20,""),"") | N20: =IF(AND(N$5>$E20,N$5<=$F20),IF(N$5=$E20+1,$C20,""),"") | O20: =IF(AND(O$5>$E20,O$5<=$F20),IF(O$5=$E20+1,$C20,""),"") | ... FA20: =IF(AND(FA$5>$E20,FA$5<=$F20),IF(FA$5=$E20+1,$C20,""),"")
A21: =Plan!A15 | B21: =Plan!C15 | C21: =Plan!D15 | D21: =Plan!I15 | E21: =Plan!K15 | F21: =Plan!L15 | G21: =Plan!O15 | H21: =IF(AND(H$5>$E21,H$5<=$F21),IF(H$5=$E21+1,$C21,""),"") | I21: =IF(AND(I$5>$E21,I$5<=$F21),IF(I$5=$E21+1,$C21,""),"") | J21: =IF(AND(J$5>$E21,J$5<=$F21),IF(J$5=$E21+1,$C21,""),"") | K21: =IF(AND(K$5>$E21,K$5<=$F21),IF(K$5=$E21+1,$C21,""),"") | L21: =IF(AND(L$5>$E21,L$5<=$F21),IF(L$5=$E21+1,$C21,""),"") | M21: =IF(AND(M$5>$E21,M$5<=$F21),IF(M$5=$E21+1,$C21,""),"") | N21: =IF(AND(N$5>$E21,N$5<=$F21),IF(N$5=$E21+1,$C21,""),"") | O21: =IF(AND(O$5>$E21,O$5<=$F21),IF(O$5=$E21+1,$C21,""),"") | ... FA21: =IF(AND(FA$5>$E21,FA$5<=$F21),IF(FA$5=$E21+1,$C21,""),"")
A22: =Plan!A16 | B22: =Plan!C16 | C22: =Plan!D16 | D22: =Plan!I16 | E22: =Plan!K16 | F22: =Plan!L16 | G22: =Plan!O16 | H22: =IF(AND(H$5>$E22,H$5<=$F22),IF(H$5=$E22+1,$C22,""),"") | I22: =IF(AND(I$5>$E22,I$5<=$F22),IF(I$5=$E22+1,$C22,""),"") | J22: =IF(AND(J$5>$E22,J$5<=$F22),IF(J$5=$E22+1,$C22,""),"") | K22: =IF(AND(K$5>$E22,K$5<=$F22),IF(K$5=$E22+1,$C22,""),"") | L22: =IF(AND(L$5>$E22,L$5<=$F22),IF(L$5=$E22+1,$C22,""),"") | M22: =IF(AND(M$5>$E22,M$5<=$F22),IF(M$5=$E22+1,$C22,""),"") | N22: =IF(AND(N$5>$E22,N$5<=$F22),IF(N$5=$E22+1,$C22,""),"") | O22: =IF(AND(O$5>$E22,O$5<=$F22),IF(O$5=$E22+1,$C22,""),"") | ... FA22: =IF(AND(FA$5>$E22,FA$5<=$F22),IF(FA$5=$E22+1,$C22,""),"")
A23: =Plan!A17 | B23: =Plan!C17 | C23: =Plan!D17 | D23: =Plan!I17 | E23: =Plan!K17 | F23: =Plan!L17 | G23: =Plan!O17 | H23: =IF(AND(H$5>$E23,H$5<=$F23),IF(H$5=$E23+1,$C23,""),"") | I23: =IF(AND(I$5>$E23,I$5<=$F23),IF(I$5=$E23+1,$C23,""),"") | J23: =IF(AND(J$5>$E23,J$5<=$F23),IF(J$5=$E23+1,$C23,""),"") | K23: =IF(AND(K$5>$E23,K$5<=$F23),IF(K$5=$E23+1,$C23,""),"") | L23: =IF(AND(L$5>$E23,L$5<=$F23),IF(L$5=$E23+1,$C23,""),"") | M23: =IF(AND(M$5>$E23,M$5<=$F23),IF(M$5=$E23+1,$C23,""),"") | N23: =IF(AND(N$5>$E23,N$5<=$F23),IF(N$5=$E23+1,$C23,""),"") | O23: =IF(AND(O$5>$E23,O$5<=$F23),IF(O$5=$E23+1,$C23,""),"") | ... FA23: =IF(AND(FA$5>$E23,FA$5<=$F23),IF(FA$5=$E23+1,$C23,""),"")
A24: =Plan!A18 | B24: =Plan!C18 | C24: =Plan!D18 | D24: =Plan!I18 | E24: =Plan!K18 | F24: =Plan!L18 | G24: =Plan!O18 | H24: =IF(AND(H$5>$E24,H$5<=$F24),IF(H$5=$E24+1,$C24,""),"") | I24: =IF(AND(I$5>$E24,I$5<=$F24),IF(I$5=$E24+1,$C24,""),"") | J24: =IF(AND(J$5>$E24,J$5<=$F24),IF(J$5=$E24+1,$C24,""),"") | K24: =IF(AND(K$5>$E24,K$5<=$F24),IF(K$5=$E24+1,$C24,""),"") | L24: =IF(AND(L$5>$E24,L$5<=$F24),IF(L$5=$E24+1,$C24,""),"") | M24: =IF(AND(M$5>$E24,M$5<=$F24),IF(M$5=$E24+1,$C24,""),"") | N24: =IF(AND(N$5>$E24,N$5<=$F24),IF(N$5=$E24+1,$C24,""),"") | O24: =IF(AND(O$5>$E24,O$5<=$F24),IF(O$5=$E24+1,$C24,""),"") | ... FA24: =IF(AND(FA$5>$E24,FA$5<=$F24),IF(FA$5=$E24+1,$C24,""),"")
A25: =Plan!A19 | B25: =Plan!C19 | C25: =Plan!D19 | D25: =Plan!I19 | E25: =Plan!K19 | F25: =Plan!L19 | G25: =Plan!O19 | H25: =IF(AND(H$5>$E25,H$5<=$F25),IF(H$5=$E25+1,$C25,""),"") | I25: =IF(AND(I$5>$E25,I$5<=$F25),IF(I$5=$E25+1,$C25,""),"") | J25: =IF(AND(J$5>$E25,J$5<=$F25),IF(J$5=$E25+1,$C25,""),"") | K25: =IF(AND(K$5>$E25,K$5<=$F25),IF(K$5=$E25+1,$C25,""),"") | L25: =IF(AND(L$5>$E25,L$5<=$F25),IF(L$5=$E25+1,$C25,""),"") | M25: =IF(AND(M$5>$E25,M$5<=$F25),IF(M$5=$E25+1,$C25,""),"") | N25: =IF(AND(N$5>$E25,N$5<=$F25),IF(N$5=$E25+1,$C25,""),"") | O25: =IF(AND(O$5>$E25,O$5<=$F25),IF(O$5=$E25+1,$C25,""),"") | ... FA25: =IF(AND(FA$5>$E25,FA$5<=$F25),IF(FA$5=$E25+1,$C25,""),"")
A26: =Plan!A20 | B26: =Plan!C20 | C26: =Plan!D20 | D26: =Plan!I20 | E26: =Plan!K20 | F26: =Plan!L20 | G26: =Plan!O20 | H26: =IF(AND(H$5>$E26,H$5<=$F26),IF(H$5=$E26+1,$C26,""),"") | I26: =IF(AND(I$5>$E26,I$5<=$F26),IF(I$5=$E26+1,$C26,""),"") | J26: =IF(AND(J$5>$E26,J$5<=$F26),IF(J$5=$E26+1,$C26,""),"") | K26: =IF(AND(K$5>$E26,K$5<=$F26),IF(K$5=$E26+1,$C26,""),"") | L26: =IF(AND(L$5>$E26,L$5<=$F26),IF(L$5=$E26+1,$C26,""),"") | M26: =IF(AND(M$5>$E26,M$5<=$F26),IF(M$5=$E26+1,$C26,""),"") | N26: =IF(AND(N$5>$E26,N$5<=$F26),IF(N$5=$E26+1,$C26,""),"") | O26: =IF(AND(O$5>$E26,O$5<=$F26),IF(O$5=$E26+1,$C26,""),"") | ... FA26: =IF(AND(FA$5>$E26,FA$5<=$F26),IF(FA$5=$E26+1,$C26,""),"")
A27: =Plan!A21 | B27: =Plan!C21 | C27: =Plan!D21 | D27: =Plan!I21 | E27: =Plan!K21 | F27: =Plan!L21 | G27: =Plan!O21 | H27: =IF(AND(H$5>$E27,H$5<=$F27),IF(H$5=$E27+1,$C27,""),"") | I27: =IF(AND(I$5>$E27,I$5<=$F27),IF(I$5=$E27+1,$C27,""),"") | J27: =IF(AND(J$5>$E27,J$5<=$F27),IF(J$5=$E27+1,$C27,""),"") | K27: =IF(AND(K$5>$E27,K$5<=$F27),IF(K$5=$E27+1,$C27,""),"") | L27: =IF(AND(L$5>$E27,L$5<=$F27),IF(L$5=$E27+1,$C27,""),"") | M27: =IF(AND(M$5>$E27,M$5<=$F27),IF(M$5=$E27+1,$C27,""),"") | N27: =IF(AND(N$5>$E27,N$5<=$F27),IF(N$5=$E27+1,$C27,""),"") | O27: =IF(AND(O$5>$E27,O$5<=$F27),IF(O$5=$E27+1,$C27,""),"") | ... FA27: =IF(AND(FA$5>$E27,FA$5<=$F27),IF(FA$5=$E27+1,$C27,""),"")
A28: =Plan!A22 | B28: =Plan!C22 | C28: =Plan!D22 | D28: =Plan!I22 | E28: =Plan!K22 | F28: =Plan!L22 | G28: =Plan!O22 | H28: =IF(AND(H$5>$E28,H$5<=$F28),IF(H$5=$E28+1,$C28,""),"") | I28: =IF(AND(I$5>$E28,I$5<=$F28),IF(I$5=$E28+1,$C28,""),"") | J28: =IF(AND(J$5>$E28,J$5<=$F28),IF(J$5=$E28+1,$C28,""),"") | K28: =IF(AND(K$5>$E28,K$5<=$F28),IF(K$5=$E28+1,$C28,""),"") | L28: =IF(AND(L$5>$E28,L$5<=$F28),IF(L$5=$E28+1,$C28,""),"") | M28: =IF(AND(M$5>$E28,M$5<=$F28),IF(M$5=$E28+1,$C28,""),"") | N28: =IF(AND(N$5>$E28,N$5<=$F28),IF(N$5=$E28+1,$C28,""),"") | O28: =IF(AND(O$5>$E28,O$5<=$F28),IF(O$5=$E28+1,$C28,""),"") | ... FA28: =IF(AND(FA$5>$E28,FA$5<=$F28),IF(FA$5=$E28+1,$C28,""),"")
A29: =Plan!A23 | B29: =Plan!C23 | C29: =Plan!D23 | D29: =Plan!I23 | E29: =Plan!K23 | F29: =Plan!L23 | G29: =Plan!O23 | H29: =IF(AND(H$5>$E29,H$5<=$F29),IF(H$5=$E29+1,$C29,""),"") | I29: =IF(AND(I$5>$E29,I$5<=$F29),IF(I$5=$E29+1,$C29,""),"") | J29: =IF(AND(J$5>$E29,J$5<=$F29),IF(J$5=$E29+1,$C29,""),"") | K29: =IF(AND(K$5>$E29,K$5<=$F29),IF(K$5=$E29+1,$C29,""),"") | L29: =IF(AND(L$5>$E29,L$5<=$F29),IF(L$5=$E29+1,$C29,""),"") | M29: =IF(AND(M$5>$E29,M$5<=$F29),IF(M$5=$E29+1,$C29,""),"") | N29: =IF(AND(N$5>$E29,N$5<=$F29),IF(N$5=$E29+1,$C29,""),"") | O29: =IF(AND(O$5>$E29,O$5<=$F29),IF(O$5=$E29+1,$C29,""),"") | ... FA29: =IF(AND(FA$5>$E29,FA$5<=$F29),IF(FA$5=$E29+1,$C29,""),"")
A30: =Plan!A24 | B30: =Plan!C24 | C30: =Plan!D24 | D30: =Plan!I24 | E30: =Plan!K24 | F30: =Plan!L24 | G30: =Plan!O24 | H30: =IF(AND(H$5>$E30,H$5<=$F30),IF(H$5=$E30+1,$C30,""),"") | I30: =IF(AND(I$5>$E30,I$5<=$F30),IF(I$5=$E30+1,$C30,""),"") | J30: =IF(AND(J$5>$E30,J$5<=$F30),IF(J$5=$E30+1,$C30,""),"") | K30: =IF(AND(K$5>$E30,K$5<=$F30),IF(K$5=$E30+1,$C30,""),"") | L30: =IF(AND(L$5>$E30,L$5<=$F30),IF(L$5=$E30+1,$C30,""),"") | M30: =IF(AND(M$5>$E30,M$5<=$F30),IF(M$5=$E30+1,$C30,""),"") | N30: =IF(AND(N$5>$E30,N$5<=$F30),IF(N$5=$E30+1,$C30,""),"") | O30: =IF(AND(O$5>$E30,O$5<=$F30),IF(O$5=$E30+1,$C30,""),"") | ... FA30: =IF(AND(FA$5>$E30,FA$5<=$F30),IF(FA$5=$E30+1,$C30,""),"")
... A33: =Plan!A27 | B33: =Plan!C27 | C33: =Plan!D27 | D33: =Plan!I27 | E33: =Plan!K27 | F33: =Plan!L27 | G33: =Plan!O27 | H33: =IF(AND(H$5>$E33,H$5<=$F33),IF(H$5=$E33+1,$C33,""),"") | I33: =IF(AND(I$5>$E33,I$5<=$F33),IF(I$5=$E33+1,$C33,""),"") | J33: =IF(AND(J$5>$E33,J$5<=$F33),IF(J$5=$E33+1,$C33,""),"") | K33: =IF(AND(K$5>$E33,K$5<=$F33),IF(K$5=$E33+1,$C33,""),"") | L33: =IF(AND(L$5>$E33,L$5<=$F33),IF(L$5=$E33+1,$C33,""),"") | M33: =IF(AND(M$5>$E33,M$5<=$F33),IF(M$5=$E33+1,$C33,""),"") | N33: =IF(AND(N$5>$E33,N$5<=$F33),IF(N$5=$E33+1,$C33,""),"") | O33: =IF(AND(O$5>$E33,O$5<=$F33),IF(O$5=$E33+1,$C33,""),"") | ... FA33: =IF(AND(FA$5>$E33,FA$5<=$F33),IF(FA$5=$E33+1,$C33,""),"")
A34: =Plan!A119 | B34: =Plan!C119 | C34: =Plan!D119 | D34: =Plan!I119 | E34: =Plan!K119 | F34: =Plan!L119 | G34: =Plan!O119 | H34: =IF(AND(H$5>$E34,H$5<=$F34),IF(H$5=$E34+1,$C34,""),"") | I34: =IF(AND(I$5>$E34,I$5<=$F34),IF(I$5=$E34+1,$C34,""),"") | J34: =IF(AND(J$5>$E34,J$5<=$F34),IF(J$5=$E34+1,$C34,""),"") | K34: =IF(AND(K$5>$E34,K$5<=$F34),IF(K$5=$E34+1,$C34,""),"") | L34: =IF(AND(L$5>$E34,L$5<=$F34),IF(L$5=$E34+1,$C34,""),"") | M34: =IF(AND(M$5>$E34,M$5<=$F34),IF(M$5=$E34+1,$C34,""),"") | N34: =IF(AND(N$5>$E34,N$5<=$F34),IF(N$5=$E34+1,$C34,""),"") | O34: =IF(AND(O$5>$E34,O$5<=$F34),IF(O$5=$E34+1,$C34,""),"") | ... FA34: =IF(AND(FA$5>$E34,FA$5<=$F34),IF(FA$5=$E34+1,$C34,""),"")
